<mujoco model="ballfoot2">
    <compiler angle="radian" meshdir="./" />
    <size njmax="500" nconmax="100" />
    <asset>
        <mesh name="base_link" file="base_link.STL" />
        <mesh name="flthigh" file="flthigh.STL" />
        <mesh name="flcalf" file="flcalf.STL" />
        <mesh name="frthigh" file="frthigh.STL" />
        <mesh name="frcalf" file="frcalf.STL" />
        <mesh name="blthigh" file="blthigh.STL" />
        <mesh name="blcalf" file="blcalf.STL" />
        <mesh name="brthigh" file="brthigh.STL" />
        <mesh name="brcalf" file="brcalf.STL" />
    </asset>
    <worldbody>
    <body name="base_link" pos="0 0 2" quat="0 0 0 1">
        <geom type="mesh" contype="0" conaffinity="0" group="1" rgba="0.75294 0.75294 0.75294 1" mesh="base_link" />
        <geom type="mesh" rgba="0.75294 0.75294 0.75294 1" mesh="base_link" />
        <inertial pos="0 0.1 0.04837" quat="0 0 0 1" mass="9.0856" diaginertia="0.30092 0.29888 0.02338" />
        <body name="flthigh" pos="-0.34 0.6 0.045" quat="0.498606 0.50139 -0.498606 -0.50139">
            <inertial pos="0.010372 -0.1751 -0.041995" quat="0.47885 0.521005 -0.491058 0.508053" mass="2.1812" diaginertia="0.069895 0.0670144 0.005092" />
            <joint name="flhip" pos="0 0 0" axis="0 0 1" limited="true" range="-0.78 0.78" type="hinge"/>
            <geom type="mesh" contype="0" conaffinity="0" group="1" rgba="0.79216 0.81961 0.93333 1" mesh="flthigh" />
            <geom type="mesh" rgba="0.79216 0.81961 0.93333 1" mesh="flthigh" />
            <body name="flcalf" pos="0.0331126 -0.55902 0">
                <inertial pos="0.0013137 -0.23597 -0.035" quat="0.707104 0.707104 0.00196824 0.00196824" mass="0.91329" diaginertia="0.0377522 0.037323 0.000604139" />
                <joint name="flknee" pos="0 0 0" axis="0 0 1" limited="true" range="-0.78 0.78" type="hinge"/>
                <geom type="mesh" contype="0" conaffinity="0" group="1" rgba="0.89804 0.91765 0.92941 1" mesh="flcalf" />
                <geom type="mesh" rgba="0.89804 0.91765 0.92941 1" mesh="flcalf" />
            </body>
        </body>
        <body name="frthigh" pos="0.34 0.6 0.045" quat="0.498606 0.50139 -0.498606 -0.50139">
            <inertial pos="0.010372 -0.1751 0.041995" quat="0.491058 0.508053 -0.47885 0.521005" mass="2.1812" diaginertia="0.069895 0.0670144 0.005092" />
            <joint name="frhip" pos="0 0 0" axis="0 0 -1" limited="true" range="-0.78 0.78" type="hinge"/>
            <geom type="mesh" contype="0" conaffinity="0" group="1" rgba="0.79216 0.81961 0.93333 1" mesh="frthigh" />
            <geom type="mesh" rgba="0.79216 0.81961 0.93333 1" mesh="frthigh" />
            <body name="frcalf" pos="0.0331126 -0.55902 0">
                <inertial pos="0.0013137 -0.23597 0.035" quat="0.707104 0.707104 0.00196824 0.00196824" mass="0.91329" diaginertia="0.0377522 0.037323 0.000604139" />
                <joint name="frknee" pos="0 0 0" axis="0 0 -1" limited="true" range="-0.78 0.78" type="hinge"/>
                <geom type="mesh" contype="0" conaffinity="0" group="1" rgba="0.89804 0.91765 0.92941 1" mesh="frcalf" />
                <geom type="mesh" rgba="0.89804 0.91765 0.92941 1" mesh="frcalf" />
            </body>
        </body>
        <body name="blthigh" pos="-0.34 -0.45 0.045" quat="0.498606 0.50139 -0.498606 -0.50139">
            <inertial pos="0.010372 -0.1751 -0.041995" quat="0.47885 0.521005 -0.491058 0.508053" mass="2.1812" diaginertia="0.069895 0.0670144 0.005092" />
            <joint name="blhip" pos="0 0 0" axis="0 0 1" limited="true" range="-0.78 0.78" type="hinge"/>
            <geom type="mesh" contype="0" conaffinity="0" group="1" rgba="0.79216 0.81961 0.93333 1" mesh="blthigh" />
            <geom type="mesh" rgba="0.79216 0.81961 0.93333 1" mesh="blthigh" />
            <body name="blcalf" pos="0.0331126 -0.55902 0">
                <inertial pos="0.0013137 -0.23597 -0.035" quat="0.707104 0.707104 0.00196824 0.00196824" mass="0.91329" diaginertia="0.0377522 0.037323 0.000604139" />
                <joint name="blknee" pos="0 0 0" axis="0 0 1" limited="true" range="-0.78 0.78" type="hinge"/>
                <geom type="mesh" contype="0" conaffinity="0" group="1" rgba="0.89804 0.91765 0.92941 1" mesh="blcalf" />
                <geom type="mesh" rgba="0.89804 0.91765 0.92941 1" mesh="blcalf" />
            </body>
        </body>
        <body name="brthigh" pos="0.34 -0.45 0.045" quat="0.498606 0.50139 -0.498606 -0.50139">
            <inertial pos="0.010372 -0.1751 0.041995" quat="0.491058 0.508053 -0.47885 0.521005" mass="2.1812" diaginertia="0.069895 0.0670144 0.005092" />
            <joint name="brhip" pos="0 0 0" axis="0 0 -1" limited="true" range="-0.78 0.78" type="hinge"/>
            <geom type="mesh" contype="0" conaffinity="0" group="1" rgba="0.79216 0.81961 0.93333 1" mesh="brthigh" />
            <geom type="mesh" rgba="0.79216 0.81961 0.93333 1" mesh="brthigh" />
            <body name="brcalf" pos="0.0331126 -0.55902 0">
                <inertial pos="0.0013137 -0.23597 0.035" quat="0.707104 0.707104 0.00196824 0.00196824" mass="0.91329" diaginertia="0.0377522 0.037323 0.000604139" />
                <joint name="brknee" pos="0 0 0" axis="0 0 -1" limited="true" range="-0.78 0.78" type="hinge"/>
                <geom type="mesh" contype="0" conaffinity="0" group="1" rgba="0.89804 0.91765 0.92941 1" mesh="brcalf" />
                <geom type="mesh" rgba="0.89804 0.91765 0.92941 1" mesh="brcalf" />
            </body>
        </body>
        </body>
    </worldbody>
</mujoco>
