<?xml version="1.0" encoding="utf-8"?>
<!-- This URDF was automatically created by SolidWorks to URDF Exporter! Originally created by Stephen Brawner (brawner@gmail.com) 
     Commit Version: 1.6.0-1-g15f4949  Build Version: 1.6.7594.29634
     For more information, please see http://wiki.ros.org/sw_urdf_exporter -->
<robot
  name="centaur_urdf">
  <link
    name="base_link">
    <inertial>
      <origin
        xyz="5.99274422863338E-08 0.0627785232806068 -0.00140559366517001"
        rpy="0 0 0" />
      <mass
        value="1.86977241288359" />
      <inertia
        ixx="0.00479191131050549"
        ixy="3.90881402194306E-09"
        ixz="-7.46774984462918E-09"
        iyy="0.0107382223914361"
        iyz="0.000736442802352788"
        izz="0.0136871237771052" />
    </inertial>
    <visual>
      <origin
        xyz="0 0 0"
        rpy="0 0 0" />
      <geometry>
        <mesh
          filename="package://centaur_urdf/meshes/base_link.STL" />
      </geometry>
      <material
        name="">
        <color
          rgba="0.752941176470588 0.752941176470588 0.752941176470588 1" />
      </material>
    </visual>
    <collision>
      <origin
        xyz="0 0 0"
        rpy="0 0 0" />
      <geometry>
        <mesh
          filename="package://centaur_urdf/meshes/base_link.STL" />
      </geometry>
    </collision>
  </link>
  <link
    name="LPelvis01">
    <inertial>
      <origin
        xyz="0.011229 -0.003225 -0.025461"
        rpy="0 0 0" />
      <mass
        value="0.10228" />
      <inertia
        ixx="3.6191E-05"
        ixy="2.8934E-06"
        ixz="-5.2913E-07"
        iyy="4.1712E-05"
        iyz="1.5198E-07"
        izz="5.3341E-05" />
    </inertial>
    <visual>
      <origin
        xyz="0 0 0"
        rpy="0 0 0" />
      <geometry>
        <mesh
          filename="package://centaur_urdf/meshes/LPelvis01.STL" />
      </geometry>
      <material
        name="">
        <color
          rgba="0.75294 0.75294 0.75294 1" />
      </material>
    </visual>
    <collision>
      <origin
        xyz="0 0 0"
        rpy="0 0 0" />
      <geometry>
        <mesh
          filename="package://centaur_urdf/meshes/LPelvis01.STL" />
      </geometry>
    </collision>
  </link>
  <joint
    name="Lhipy"
    type="revolute">
    <origin
      xyz="0.12 0.07 0"
      rpy="1.5708 0 0" />
    <parent
      link="base_link" />
    <child
      link="LPelvis01" />
    <axis
      xyz="0 0 -1" />
    <limit
      lower="-2"
      upper="2"
      effort="0"
      velocity="0" />
  </joint>
  <link
    name="LPelvis02">
    <inertial>
      <origin
        xyz="0.030747 0.043959 -0.053175"
        rpy="0 0 0" />
      <mass
        value="1.2721" />
      <inertia
        ixx="0.0039413"
        ixy="0.00010999"
        ixz="2.6582E-05"
        iyy="0.0030337"
        iyz="-0.00066066"
        izz="0.0057264" />
    </inertial>
    <visual>
      <origin
        xyz="0 0 0"
        rpy="0 0 0" />
      <geometry>
        <mesh
          filename="package://centaur_urdf/meshes/LPelvis02.STL" />
      </geometry>
      <material
        name="">
        <color
          rgba="0.64706 0.61961 0.58824 1" />
      </material>
    </visual>
    <collision>
      <origin
        xyz="0 0 0"
        rpy="0 0 0" />
      <geometry>
        <mesh
          filename="package://centaur_urdf/meshes/LPelvis02.STL" />
      </geometry>
    </collision>
  </link>
  <joint
    name="Lhipz"
    type="revolute">
    <origin
      xyz="0.02 -0.02 -0.025"
      rpy="-1.5708 0 0" />
    <parent
      link="LPelvis01" />
    <child
      link="LPelvis02" />
    <axis
      xyz="0 0 -1" />
    <limit
      lower="-2"
      upper="2"
      effort="0"
      velocity="0" />
  </joint>
  <link
    name="LThigh">
    <inertial>
      <origin
        xyz="0.068249 -0.10404 0.027078"
        rpy="0 0 0" />
      <mass
        value="1.3138" />
      <inertia
        ixx="0.03289"
        ixy="0.019361"
        ixz="0.00061008"
        iyy="0.016077"
        iyz="-0.00092999"
        izz="0.047578" />
    </inertial>
    <visual>
      <origin
        xyz="0 0 0"
        rpy="0 0 0" />
      <geometry>
        <mesh
          filename="package://centaur_urdf/meshes/LThigh.STL" />
      </geometry>
      <material
        name="">
        <color
          rgba="0.75294 0.75294 0.75294 1" />
      </material>
    </visual>
    <collision>
      <origin
        xyz="0 0 0"
        rpy="0 0 0" />
      <geometry>
        <mesh
          filename="package://centaur_urdf/meshes/LThigh.STL" />
      </geometry>
    </collision>
  </link>
  <joint
    name="Lhipx"
    type="revolute">
    <origin
      xyz="0.13 0 -0.055"
      rpy="1.5708 0 1.5708" />
    <parent
      link="LPelvis02" />
    <child
      link="LThigh" />
    <axis
      xyz="0 0 -1" />
    <limit
      lower="-2"
      upper="2"
      effort="0"
      velocity="0" />
  </joint>
  <link
    name="LCalf">
    <inertial>
      <origin
        xyz="-0.075262 -0.10701 0.035"
        rpy="0 0 0" />
      <mass
        value="0.42989" />
      <inertia
        ixx="0.0055581"
        ixy="-0.003716"
        ixz="-2.1124E-10"
        iyy="0.0028884"
        iyz="-3.3819E-10"
        izz="0.0080157" />
    </inertial>
    <visual>
      <origin
        xyz="0 0 0"
        rpy="0 0 0" />
      <geometry>
        <mesh
          filename="package://centaur_urdf/meshes/LCalf.STL" />
      </geometry>
      <material
        name="">
        <color
          rgba="0.75294 0.75294 0.75294 1" />
      </material>
    </visual>
    <collision>
      <origin
        xyz="0 0 0"
        rpy="0 0 0" />
      <geometry>
        <mesh
          filename="package://centaur_urdf/meshes/LCalf.STL" />
      </geometry>
    </collision>
  </link>
  <joint
    name="Lkneex"
    type="revolute">
    <origin
      xyz="0.30717 -0.46824 0"
      rpy="0 0 0" />
    <parent
      link="LThigh" />
    <child
      link="LCalf" />
    <axis
      xyz="0 0 -1" />
    <limit
      lower="-1"
      upper="1"
      effort="0"
      velocity="0" />
  </joint>
  <link
    name="LFoot">
    <inertial>
      <origin
        xyz="0.0075881 -0.048108 0.01"
        rpy="0 0 0" />
      <mass
        value="0.13962" />
      <inertia
        ixx="5.5783E-05"
        ixy="6.6601E-06"
        ixz="-1.7724E-12"
        iyy="0.00030802"
        iyz="1.4707E-12"
        izz="0.00030837" />
    </inertial>
    <visual>
      <origin
        xyz="0 0 0"
        rpy="0 0 0" />
      <geometry>
        <mesh
          filename="package://centaur_urdf/meshes/LFoot.STL" />
      </geometry>
      <material
        name="">
        <color
          rgba="0.75294 0.75294 0.75294 1" />
      </material>
    </visual>
    <collision>
      <origin
        xyz="0 0 0"
        rpy="0 0 0" />
      <geometry>
        <mesh
          filename="package://centaur_urdf/meshes/LFoot.STL" />
      </geometry>
    </collision>
  </link>
  <joint
    name="Lanklex"
    type="revolute">
    <origin
      xyz="-0.32217 -0.45805 0.025"
      rpy="0 0 0" />
    <parent
      link="LCalf" />
    <child
      link="LFoot" />
    <axis
      xyz="0 0 1" />
    <limit
      lower="-0.3"
      upper="0.3"
      effort="0"
      velocity="0" />
  </joint>
  <link
    name="RPelvis01">
    <inertial>
      <origin
        xyz="-0.011229 -0.003225 -0.025461"
        rpy="0 0 0" />
      <mass
        value="0.10228" />
      <inertia
        ixx="3.6191E-05"
        ixy="-2.8934E-06"
        ixz="5.2913E-07"
        iyy="4.1712E-05"
        iyz="1.5198E-07"
        izz="5.3341E-05" />
    </inertial>
    <visual>
      <origin
        xyz="0 0 0"
        rpy="0 0 0" />
      <geometry>
        <mesh
          filename="package://centaur_urdf/meshes/RPelvis01.STL" />
      </geometry>
      <material
        name="">
        <color
          rgba="0.75294 0.75294 0.75294 1" />
      </material>
    </visual>
    <collision>
      <origin
        xyz="0 0 0"
        rpy="0 0 0" />
      <geometry>
        <mesh
          filename="package://centaur_urdf/meshes/RPelvis01.STL" />
      </geometry>
    </collision>
  </link>
  <joint
    name="Rhipy"
    type="revolute">
    <origin
      xyz="-0.12 0.07 0"
      rpy="1.5708 0 0" />
    <parent
      link="base_link" />
    <child
      link="RPelvis01" />
    <axis
      xyz="0 0 -1" />
    <limit
      lower="-2"
      upper="2"
      effort="0"
      velocity="0" />
  </joint>
  <link
    name="RPelvis02">
    <inertial>
      <origin
        xyz="-0.030747 0.043959 -0.053175"
        rpy="0 0 0" />
      <mass
        value="1.2721" />
      <inertia
        ixx="0.0039413"
        ixy="-0.00010998"
        ixz="-2.6601E-05"
        iyy="0.0030337"
        iyz="-0.00066067"
        izz="0.0057264" />
    </inertial>
    <visual>
      <origin
        xyz="0 0 0"
        rpy="0 0 0" />
      <geometry>
        <mesh
          filename="package://centaur_urdf/meshes/RPelvis02.STL" />
      </geometry>
      <material
        name="">
        <color
          rgba="0.64706 0.61961 0.58824 1" />
      </material>
    </visual>
    <collision>
      <origin
        xyz="0 0 0"
        rpy="0 0 0" />
      <geometry>
        <mesh
          filename="package://centaur_urdf/meshes/RPelvis02.STL" />
      </geometry>
    </collision>
  </link>
  <joint
    name="Rhipz"
    type="revolute">
    <origin
      xyz="-0.02 -0.02 -0.025"
      rpy="-1.5708 0 0" />
    <parent
      link="RPelvis01" />
    <child
      link="RPelvis02" />
    <axis
      xyz="0 0 -1" />
    <limit
      lower="-2"
      upper="2"
      effort="0"
      velocity="0" />
  </joint>
  <link
    name="RThigh">
    <inertial>
      <origin
        xyz="-0.068248591184368 -0.104037584054621 0.0270775562011833"
        rpy="0 0 0" />
      <mass
        value="1.31379565424727" />
      <inertia
        ixx="0.0328896081972683"
        ixy="-0.0193609931199482"
        ixz="-0.000610076143023301"
        iyy="0.0160766711006057"
        iyz="-0.000929994991955905"
        izz="0.0475775788276022" />
    </inertial>
    <visual>
      <origin
        xyz="0 0 0"
        rpy="0 0 0" />
      <geometry>
        <mesh
          filename="package://centaur_urdf/meshes/RThigh.STL" />
      </geometry>
      <material
        name="">
        <color
          rgba="0.752941176470588 0.752941176470588 0.752941176470588 1" />
      </material>
    </visual>
    <collision>
      <origin
        xyz="0 0 0"
        rpy="0 0 0" />
      <geometry>
        <mesh
          filename="package://centaur_urdf/meshes/RThigh.STL" />
      </geometry>
    </collision>
  </link>
  <joint
    name="Rhipx"
    type="revolute">
    <origin
      xyz="-0.13 0 -0.055"
      rpy="1.5708 0 -1.5708" />
    <parent
      link="RPelvis02" />
    <child
      link="RThigh" />
    <axis
      xyz="0 0 -1" />
    <limit
      lower="-2"
      upper="2"
      effort="0"
      velocity="0" />
  </joint>
  <link
    name="RCalf">
    <inertial>
      <origin
        xyz="0.075262 -0.10701 0.035"
        rpy="0 0 0" />
      <mass
        value="0.42989" />
      <inertia
        ixx="0.0055581"
        ixy="0.003716"
        ixz="2.4682E-10"
        iyy="0.0028884"
        iyz="-3.1279E-10"
        izz="0.0080157" />
    </inertial>
    <visual>
      <origin
        xyz="0 0 0"
        rpy="0 0 0" />
      <geometry>
        <mesh
          filename="package://centaur_urdf/meshes/RCalf.STL" />
      </geometry>
      <material
        name="">
        <color
          rgba="0.75294 0.75294 0.75294 1" />
      </material>
    </visual>
    <collision>
      <origin
        xyz="0 0 0"
        rpy="0 0 0" />
      <geometry>
        <mesh
          filename="package://centaur_urdf/meshes/RCalf.STL" />
      </geometry>
    </collision>
  </link>
  <joint
    name="Rkneex"
    type="revolute">
    <origin
      xyz="-0.30717 -0.46824 0"
      rpy="0 0 0" />
    <parent
      link="RThigh" />
    <child
      link="RCalf" />
    <axis
      xyz="0 0 -1" />
    <limit
      lower="-1"
      upper="1"
      effort="0"
      velocity="0" />
  </joint>
  <link
    name="RFoot">
    <inertial>
      <origin
        xyz="-0.0075881 -0.048108 0.01"
        rpy="0 0 0" />
      <mass
        value="0.13962" />
      <inertia
        ixx="5.5783E-05"
        ixy="-6.6601E-06"
        ixz="-1.7724E-12"
        iyy="0.00030802"
        iyz="-1.4707E-12"
        izz="0.00030837" />
    </inertial>
    <visual>
      <origin
        xyz="0 0 0"
        rpy="0 0 0" />
      <geometry>
        <mesh
          filename="package://centaur_urdf/meshes/RFoot.STL" />
      </geometry>
      <material
        name="">
        <color
          rgba="0.75294 0.75294 0.75294 1" />
      </material>
    </visual>
    <collision>
      <origin
        xyz="0 0 0"
        rpy="0 0 0" />
      <geometry>
        <mesh
          filename="package://centaur_urdf/meshes/RFoot.STL" />
      </geometry>
    </collision>
  </link>
  <joint
    name="Ranklex"
    type="revolute">
    <origin
      xyz="0.32217 -0.45805 0.025"
      rpy="0 0 0" />
    <parent
      link="RCalf" />
    <child
      link="RFoot" />
    <axis
      xyz="0 0 -1" />
    <limit
      lower="-0.3"
      upper="0.3"
      effort="0"
      velocity="0" />
  </joint>
</robot>